Ran 1 tests in 0.020s
FAILED (failures=1, errors=0)
test_executor_to_debugger (__main__.TestDeveloper.test_executor_to_debugger)
Traceback (most recent call last):
  File "/Users/ian/dev/projects/agents/local/seclorum/tests/test_developer.py", line 108, in test_executor_to_debugger
    self.assertIn(status, ["generated", "tested", "executed", "debugged"], f"Unexpected status: {status}")
AssertionError: 'failed' not found in ['generated', 'tested', 'executed', 'debugged'] : Unexpected status: failed

